Workbook

Sheet porcionados
B1: PORCIONADOS | AF1: dólar
B2: ENTRADA | AB2: ACUMULADO | AC2: precio | AD2: Total | AF2: 40.216
A3: Códigos | B3: Productos | AB3: kls. | AC3: U$S | AD3: U$S
A4: 3000 | B4: Asado 13 costillas Pasto | AB4: =SUM(C4:AA4) -> 6654.6 | AC4: =+VNR!G4 -> 4.2151137 | AD4: =-ABS(AB4*AC4) -> -28049.895
A5: 3001 | B5: Asado 13 costillas s/p Pasto | AB5: 12007.3 | AC5: =+VNR!G5 -> 4.1501137 | AD5: =-ABS(AB5*AC5) -> -49831.66
A6: 3010 | B6: Asado 13/C (Grano) | AB6: 2979.8 | AD6: =-ABS(AB6*AC6) -> 0
A7: 3011 | B7: Asado 13 costillas Grano s/p | AB7: 64367.7 | AC7: =hacienda!O44 -> 5.8794795 | AD7: -378448.57
A8: 3911 | B8: Asado 13/c s/pulpon (grano) Compra | AB8: 9558.7 | AC8: 6.63 | AD8: -63374.181
A9: 4000 | B9: Falda con hueso Pasto | AB9: 14181.3 | AC9: =+VNR!G6 -> 3.8501137 | AD9: -54599.617
A10: 4003 | B10: Vacio (Bolsa) | AB10: 1027.2 | AD10: =-ABS(AB10*AC10) -> 0
A11: 4010 | B11: Falda con hueso Grano | AB11: 20608.6 | AC11: =+VNR!G7 -> 4.5501137 | AD11: -93771.473 | AE11: =SUM(AD4:AD11) -> -668075.4
A12: 4403 | B12: Entraña Gruesa Fresca | AB12: 1425.17 | AC12: =+VNR!G8 -> 5.2481746 | AD12: -7479.541
A13: 4404 | B13: Entraña fina | AB13: 71.9 | AC13: 12.77 | AD13: -918.163
A14: 4407 | B14: Quijada | AB14: 2284.77 | AC14: =+VNR!G9 -> 5.9342413 | AD14: -13558.376
A15: 4411 | B15: Mondongo | AB15: =SUM(C15:AA15) -> 0 | AC15: =180/40.18 -> 4.4798407 | AD15: =-ABS(AB15*AC15) -> 0
A16: 4470 | B16: Entraña Fina | AB16: 8365.7 | AC16: =+AC11 -> 4.5501137 | AD16: -38064.886
A17: 4490 | B17: TRIMMING ESPECIAL | AB17: =SUM(C17:AA17) -> 0 | AC17: 3.1 | AD17: =-ABS(AB17*AC17) -> 0
A18: 4503 | B18: Entraña Gruesa Fresca | AB18: 2139.93 | AC18: =+AC12 -> 5.2481746 | AD18: -11230.726
A19: 4514 | B19: Chinchulines | AB19: 376.53 | AC19: =125.28/40.48 -> 3.0948617 | AD19: -1165.3083
A20: 4516 | B20: Mollejas | AB20: 988.61 | AC20: =238.6/40.48 -> 5.8942688 | AD20: -5827.1331
A21: 4543 | B21: Riñon c/grasa | AB21: 453.84 | AC21: 1.71 | AD21: -776.0664
A22: 4607 | B22: Quijada Feedlot Fresca | AB22: 2163.64 | AC22: =+AC14 -> 5.9342413 | AD22: -12839.562
A23: 9407 | B23: Quijadas - Cheek Meat | AB23: =SUM(C23:AA23) -> 0 | AC23: =+AC14 -> 5.9342413 | AD23: =-ABS(AB23*AC23) -> 0
A24: 9408 | B24: Carne Chica | AB24: 48 | AC24: 4.5 | AD24: -216
A25: 9490 | B25: Trimmings Especial | AB25: 144 | AC25: 4.84 | AD25: -696.96
A26: 9607 | B26: Quijada | AB26: =SUM(C26:AA26) -> 0 | AC26: =+AC23 -> 5.9342413 | AD26: =-ABS(AB26*AC26) -> 0
A27: 437016 | B27: Bife Ancho 7/c 1x1 GF | AB27: =SUM(C27:AA27) -> 0 | AC27: =1105/1.1391184/40.3 -> 24.07068 | AD27: =-ABS(AB27*AC27) -> 0
A28: 438031 | B28: Bife Angosto Vila Congelado | AB28: =SUM(C28:AA28) -> 0 | AC28: =+VNR!G15 -> 23.836515 | AD28: =-ABS(AB28*AC28) -> 0
A29: 438037 | B29: Osobuco Vila Cong. | AB29: =SUM(C29:AA29) -> 0 | AC29: =595/1.1391184/40.3 -> 12.961136 | AD29: =-ABS(AB29*AC29) -> 0
A30: 438124 | B30: Colita de Cuadril Vila Congelada | AB30: =SUM(C30:AA30) -> 0 | AC30: 12.7 | AD30: =-ABS(AB30*AC30) -> 0
A31: 439010 | B31: Chuck Vila | AB31: =SUM(C31:AA31) -> 0 | AC31: 12.802 | AD31: =-ABS(AB31*AC31) -> 0
A32: 439016 | B32: Bife Ancho Vila | AB32: =SUM(C32:AA32) -> 0 | AC32: 28.789 | AD32: =-ABS(AB32*AC32) -> 0
A33: 439070 | B33: Entraña Fina | AB33: =SUM(C33:AA33) -> 0 | AC33: =+AC13 -> 12.77 | AD33: =-ABS(AB33*AC33) -> 0
A34: 439130 | B34: Lomo Vila | AB34: =SUM(C34:AA34) -> 0 | AC34: =1055/1.1391184/40.3 -> 22.981509 | AD34: =-ABS(AB34*AC34) -> 0
A35: 439909 | B35: Lomito de Paleta Vila | AB35: =SUM(C35:AA35) -> 0 | AC35: 8 | AD35: =-ABS(AB35*AC35) -> 0
A36: 442070 | B36: Entraña Fina EL RANCHO | AB36: =SUM(C36:AA36) -> 0 | AC36: =720/1.1391184/40.3 -> 15.684063 | AD36: =-ABS(AB36*AC36) -> 0
A37: 980006 | B37: Sobrante - Aguja | AB37: 657.91 | AC37: 7.4 | AD37: -4868.534
A38: 980011 | B38: Sobrante - Denver | AB38: 66.68 | AC38: =+AC32 -> 28.789 | AD38: -1919.6505
A39: 980012 | B39: Sobrante - Paleta | AB39: =SUM(C39:AA39) -> 0 | AC39: 5.7 | AD39: =-ABS(AB39*AC39) -> 0
A40: 980016 | B40: Sobrante - Bife Ancho | AB40: 83.97 | AC40: =392/1.1391184/40.48 -> 8.5011308 | AD40: -713.83995
...

Sheet asados
B2: entrada de Materia prima | C2: 46235 | D2: 46237 | E2: 46238 | F2: 46239 | G2: 46240 | H2: 46241 | I2: 46242 | J2: 46244 | K2: 46245 | L2: 46246 | M2: 46247 | N2: 46248 | O2: 46249 | P2: 46251 | Q2: 46252 | R2: 46253 | S2: 46254 | T2: 46255 | U2: 46256 | V2: 46257 | W2: 46258 | X2: 46259 | Y2: 46260 | Z2: 46261 | AA2: 46262 | AB2: ACUMULADO | AC2: precio | AD2: Total
A3: código | B3: Producto | C3: kls. | D3: kls. | E3: kls. | F3: kls. | G3: kls. | H3: kls. | I3: kls. | J3: kls. | K3: kls. | L3: kls. | M3: kls. | N3: kls. | O3: kls. | P3: kls. | Q3: kls. | R3: kls. | S3: kls. | T3: kls. | U3: kls. | V3: kls. | W3: kls. | X3: kls. | Y3: kls. | Z3: kls. | AA3: kls. | AB3: kls. | AC3: U$S | AD3: U$S
A4: 3000 | B4: Asado 13 costillas Pasto | F4: 538.1 | I4: 242 | J4: 262.2 | M4: 742.9 | O4: 31.1 | AB4: =SUM(C4:AA4) -> 1816.3 | AC4: =-VNR!G5 -> -4.1501137 | AD4: =AB4*AC4 -> -7537.8515
A5: 3001 | B5: Asado 13 costillas s/p Pasto | E5: 1864.2 | G5: 1375.5 | I5: 1575.2 | J5: 3531.8 | M5: 3098.1 | N5: 1638.1 | O5: 1486.8 | AB5: 14569.7 | AC5: =-VNR!G4 -> -4.2151137 | AD5: -61412.942 | AF5: $ c/imp.
A6: 3011 | B6: Asado 13 costillas Grano s/p | D6: 12629.9 | E6: 12628.9 | F6: 12379.2 | G6: 14195.5 | H6: 11974.4 | I6: 4156.7 | J6: 15211.2 | L6: 14129.4 | M6: 3726.5 | N6: 6379.1 | O6: 8753.1 | AB6: 116163.9 | AC6: =-hacienda!O19 -> 0 | AD6: =AB6*AC6 -> 0 | AF6: =+AC6*1.1391184*40.48 -> 0
A7: 3101 | B7: Asado 13 costillas Pasto s/p Nirea | AB7: =SUM(C7:AA7) -> 0 | AC7: =-VNR!G13 -> -4.3891947 | AD7: =AB7*AC7 -> 0
A8: 3911 | B8: Asado 13 costillas Grano s/p Nirea | AB8: =SUM(C8:AA8) -> 0 | AC8: =-VNR!G12 -> -5.1391947 | AD8: =AB8*AC8 -> 0
A9: 4000 | B9: Falda con hueso Pasto | D9: 1725.8 | F9: 2000.7 | G9: 854.4 | H9: 1728.4 | I9: 1370.8 | J9: 290.3 | L9: 832.7 | N9: 2238.9 | O9: 439.3 | AB9: 11481.3 | AC9: =-VNR!G6 -> -3.8501137 | AD9: -44204.31
A10: 4010 | B10: Falda con hueso Grano | D10: 5699.9 | E10: 5970 | F10: 4718.8 | H10: 3910 | I10: 2466.7 | J10: 1743.5 | L10: 5070.1 | M10: 2739.1 | N10: 2512.4 | O10: 3010.8 | AB10: 37841.3 | AC10: =-VNR!G7 -> -4.5501137 | AD10: -172182.22
A11: 980039 | B11: Sobrante - falda | D11: 47.47 | E11: 30.61 | F11: 30.97 | G11: 35.64 | H11: 34.38 | I11: 3.82 | K11: 271.9 | L11: 22 | M11: 1179.69 | N11: 359.04 | O11: 88.05 | AB11: 2103.57 | AC11: =+AC9 -> -3.8501137 | AD11: -8098.9836
A12: 980060 | B12: Sobrante - Asado 980060 | C12: 167.91 | D12: 1502.59 | E12: 547.79 | F12: 424.27 | G12: 486.26 | H12: 410.12 | I12: 855.42 | J12: 831.98 | K12: 1190.17 | L12: 491.92 | M12: 339.62 | N12: 239.63 | O12: 214.87 | AB12: 7702.55 | AC12: =+AC5 -> -4.2151137 | AD12: -32467.124
A13: 980090 | B13: Sobrante - Trimming | D13: 340.98 | E13: 972.04 | F13: 590.81 | G13: 505.35 | H13: 536.53 | I13: 90.45 | J13: 1015.06 | L13: 987.07 | M13: 723.5 | N13: 119.92 | O13: 72.11 | AB13: 5953.82 | AC13: -4.5 | AD13: -26792.19
A14: 980091 | B14: Sobrante - Manta | H14: 9.67 | L14: 5.53 | N14: 108.92 | O14: 13.13 | AB14: 137.25 | AC14: -16.543 | AD14: -2270.5267
A15: 441160 | B15: Asado 1 Costilla UMI | AB15: =SUM(C15:AA15) -> 0 | AC15: -20.571 | AD15: =AB15*AC15 -> 0
A16: 441860 | B16: Asado 8c (manta) UMI | AB16: =SUM(C16:AA16) -> 0 | AC16: -15.512 | AD16: =AB16*AC16 -> 0
A17: 2000008 | B17: Recorte (C.F.) | H17: 16.97 | J17: 20.21 | L17: 50.03 | O17: 68.44 | AB17: 155.65 | AC17: -4.5 | AD17: -700.425
A18: 1987420 | B18: Brazuelo s/h c/conical GF Angus | D18: 324.5 | E18: 86.77 | F18: 195.94 | G18: 328.14 | H18: 228.13 | I18: 21.97 | J18: 88.64 | AB18: =SUM(C18:AA18) -> 1274.09 | AD18: =-AB18*AC18 -> 0
A19: 1987434 | B19: Garron s/h GF Angus | J19: 279.58 | M19: 331.98 | N19: 370.87 | O19: 195.55 | AB19: =SUM(C19:AA19) -> 1177.98 | AD19: =-AB19*AC19 -> 0
A20: 16018990 | B20: Asado 4c Manta Grano | L20: 2238.04
A21: 16101790 | B21: ASADO | AB21: =SUM(C21:AA21) -> 0 | AC21: =-VNR!G18 -> -11.770102 | AD21: =AB21*AC21 -> 0
A22: 16103290 | B22: ASADO 3C | AB22: =SUM(C22:AA22) -> 0 | AC22: =-VNR!G19 -> -11.770102 | AD22: =AB22*AC22 -> 0
A23: 16105240 | B23: ASADO NIREA | AB23: =SUM(C23:AA23) -> 0 | AC23: =-VNR!G20 -> -11.960102 | AD23: =AB23*AC23 -> 0
A24: 16601910 | B24: ASADO 5C | AB24: =SUM(C24:AA24) -> 0 | AC24: =-VNR!G21 -> -3.6301016 | AD24: =AB24*AC24 -> 0
A25: 17001910 | B25: ASADO CON HUESO | AB25: =SUM(C25:AA25) -> 0 | AC25: =-VNR!G22 -> -3.1101016 | AD25: =AB25*AC25 -> 0
A26: 17071910 | B26: ASADO C/H TRASERO | AB26: =SUM(C26:AA26) -> 0 | AC26: =-VNR!G23 -> -3.6601016 | AD26: =AB26*AC26 -> 0
A27: 18001510 | B27: Falda Nirea Pasto (bins) | AB27: =SUM(C27:AA27) -> 0 | AC27: =-VNR!G10 -> -3.1540168 | AD27: =AB27*AC27 -> 0
A28: 18001511 | B28: Falda Nirea Grano (bins) | AB28: =SUM(C28:AA28) -> 0 | AC28: =-VNR!G11 -> -4.3452224 | AD28: =AB28*AC28 -> 0
A29: 18001830 | B29: FALDA C/H BOV CONG. BLOQ. | AB29: =SUM(C29:AA29) -> 0 | AC29: =-VNR!G10 -> -3.1540168 | AD29: =AB29*AC29 -> 0
A30: 25169820 | B30: ASADO SIN HUESO | AB30: =SUM(C30:AA30) -> 0 | AC30: =-VNR!G26 -> -13.390117 | AD30: =AB30*AC30 -> 0
A31: 21765230 | B31: Falda s/h Taurus | K31: 8703.47 | AB31: 8703.47 | AC31: =-VNR!G25 -> -7.2601016 | AD31: -63188.077
A32: 21769820 | B32: Falda s/h Grano | D32: 2089.11 | E32: 1456.51 | F32: 944.63 | G32: 2246.42 | H32: 1757.97 | I32: 6464.73 | J32: 2999.56 | K32: 2354.59 | L32: 1777.97 | M32: 17.49 | N32: 3120.18 | O32: 2081.71 | AB32: 27310.87 | AC32: =-VNR!G24 -> -7.3601016 | AD32: -201010.78
B33: Total | C33: =SUM(C4:C32) -> 167.91 | D33: 24360.25 | E33: 23556.82 | F33: 21823.42 | G33: 20027.21 | H33: 20606.57 | I33: 17247.79 | J33: 26274.03 | K33: 12520.13 | L33: 25604.76 | M33: 12898.88 | N33: 17087.06 | O33: 16454.96 | P33: =SUM(P4:P32) -> 0 | Q33: =SUM(Q4:Q32) -> 0 | R33: =SUM(R4:R32) -> 0 | S33: =SUM(S4:S32) -> 0 | T33: =SUM(T4:T32) -> 0 | U33: =SUM(U4:U32) -> 0 | V33: =SUM(V4:V32) -> 0 | W33: =SUM(W4:W32) -> 0 | ... AA33: =SUM(AA4:AA32) -> 0 | AB33: 236391.75 | AD33: =SUM(AD4:AD32) -> -619865.42
B35: Salida Producto Final | C35: =C2 -> 46235 | D35: 46237 | E35: 46238 | F35: 46239 | G35: 46240 | H35: 46241 | I35: 46242 | J35: 46244 | K35: 46245 | L35: 46246 | M35: 46247 | N35: 46248 | O35: 46249 | P35: 46251 | Q35: 46252 | R35: 46253 | S35: 46254 | T35: 46255 | U35: 46256 | V35: 46257 | W35: 46258 | X35: 46259 | Y35: 46260 | Z35: 46261 | AA35: 46262 | AB35: ACUMULADO | AC35: precio | AD35: Total | AG35: Envasado
A36: código | B36: Producto | C36: kls. | D36: kls. | E36: kls. | F36: kls. | G36: kls. | H36: kls. | I36: kls. | J36: kls. | K36: kls. | L36: kls. | M36: kls. | N36: kls. | O36: kls. | P36: kls. | Q36: kls. | R36: kls. | S36: kls. | T36: kls. | U36: kls. | V36: kls. | W36: kls. | X36: kls. | Y36: kls. | Z36: kls. | AA36: kls. | AB36: kls. | AC36: U$S | AD36: U$S | AG36: U$S total x kg
A37: 13390 | B37: TRIMMINGS ANGUS 80 CL (13) | D37: 136.05 | E37: 81.63 | G37: 108.84 | H37: 81.63 | J37: 27.21 | L37: 136.05 | M37: 217.68 | N37: 272.1 | AB37: =SUM(C37:AA37) -> 1061.19 | AC37: 5.5 | AD37: =AB37*AC37 -> 5836.545 | AE37: =+AD37*0.03 -> 175.09635 | AF37: =-AD37*0.015 -> -87.548175 | AG37: =-envases!BL19*AB37 -> -56.251249
A38: 437060 | B38: ASADO TIRA 8/C (Vacum pack) GF | D38: 270.52 | E38: 620.73 | F38: 671.33 | G38: 945.58 | H38: 145.63 | I38: 1864.76 | J38: 974.05 | L38: 655.51 | N38: 758.96 | AB38: =SUM(C38:AA38) -> 6907.07 | AC38: =envases!J106 -> 12.916046 | AD38: 89212.032 | AG38: =-envases!I121*AB38 -> -2090.9908
A39: 437660 | B39: Asado (al vacio) 8 costillas | D39: 35.99 | E39: 983.68 | F39: 656.75 | G39: 391.57 | I39: 22.59 | J39: 279.76 | L39: 113.85 | N39: 562.88 | O39: 16.25 | AB39: 3063.32 | AC39: =envases!J174 -> 12.170889 | AD39: 37283.328 | AG39: =-envases!I189*AB39 -> -1027.2349
A40: 438160 | B40: Asado del Rey VILA cong. | AB40: =SUM(C40:AA40) -> 0 | AC40: =envases!E399 -> 15.772479 | AD40: =AB40*AC40 -> 0 | AG40: =-envases!D416*AB40 -> 0
A41: 438260 | B41: Asado 2 y medio Vila | AB41: =SUM(C41:AA41) -> 0 | AC41: =690/40.18 -> 17.172723 | AD41: =AB41*AC41 -> 0 | AG41: =-envases!D552*AB41 -> 0
A42: 438360 | B42: Asado 3/c en tiras Vila | D42: 136.14 | E42: 243.73 | F42: 59.66 | G42: 230.86 | H42: 95.93 | I42: 144.29 | J42: 243.78 | L42: 59.9 | M42: 145.03 | N42: 103.66 | O42: 49.69 | AB42: 1512.67 | AC42: =envases!E418 -> 14.778937 | AD42: 22355.654 | AG42: =-envases!D435*AB42 -> -1134.0942
...

Sheet logs
B2: entrada de Materia prima y aditivos | AB2: ACUMULADO | AC2: precio | AD2: Total
A3: código | B3: Producto | AB3: kls. | AC3: U$S | AD3: U$S
A4: 980006 | B4: Sobrante - Aguja | AB4: =SUM(C4:AA4) -> 0 | AC4: 7.6 | AD4: =AC4*AB4 -> 0
A5: 980024 | B5: Sobrante - Colita | AB5: 113.3 | AC5: =681/1.1391184/40.48 -> 14.768546 | AD5: 1673.2763
A6: 980026 | B6: Sobrante - Cuadrada | AB6: =SUM(C6:AA6) -> 0 | AC6: 6.01 | AD6: =AC6*AB6 -> 0
A7: 980090 | B7: Sobrante - Trimming | AB7: 1171.59 | AC7: 5.5 | AD7: 6443.745
A8: 980091 | B8: Sobrante - Manta 980091 | AB8: 63.88 | AC8: 5.5 | AD8: 351.34
A9: 991026 | B9: Cuadrada China | AB9: =SUM(C9:AA9) -> 0 | AC9: 6.01 | AD9: =AC9*AB9 -> 0
A10: 2000006 | B10: Aguja | AB10: =SUM(C10:AA10) -> 0 | AC10: 6.3 | AD10: =AC10*AB10 -> 0
A11: 2000008 | B11: Recorte (C.F) | AB11: 5034.05 | AC11: 4.5 | AD11: 22653.225
A12: 2000012 | B12: Paleta sin marucha Logs | AB12: 4856.19 | AC12: 7.4 | AD12: 35935.806
A13: 2000022 | B13: Nalga c/t logs | AB13: 21.48 | AC13: 6.5 | AD13: 139.62
A14: 2000023 | B14: Nalga s/t logs | AB14: =SUM(C14:AA14) -> 0 | AC14: 6.5 | AD14: =AC14*AB14 -> 0
A15: 2000026 | B15: Cuadrada Logs | AB15: 3861.29 | AC15: 6.5 | AD15: 25098.385
A16: 2000027 | B16: Bola de Lomo Logs | AB16: 16570.09 | AC16: 6.5 | AD16: 107705.59
A17: 2000028 | B17: Peceto Logs | AB17: =SUM(C17:AA17) -> 0 | AC17: 6.5 | AD17: =AC17*AB17 -> 0
A18: 2000031 | B18: Bife Angosto Pasto | AB18: =SUM(C18:AA18) -> 0 | AC18: 7.4 | AD18: =AC18*AB18 -> 0
A19: 2000032 | B19: Tapa de Vacio Logs | AB19: 3630.35 | AC19: 5.5 | AD19: 19966.925
A20: 2000035 | B20: Puntas de Matambre Logs | AB20: 910.9 | AC20: 5.5 | AD20: 5009.95
A21: 2000041 | B21: Arañita logs (grano) | AB21: =SUM(C21:AA21) -> 0 | AC21: 5.5 | AD21: =AC21*AB21 -> 0
A22: 2000060 | B22: Tapa de Asado s/h logs | AB22: 874.78 | AC22: 5.5 | AD22: 4811.29
A23: 2000090 | B23: Sobrante Mat. Prima preparada para logs | AB23: 2696.92 | AC23: 5.5 | AD23: 14833.06
A24: 2000091 | B24: Manta Logs | AB24: 12339.51 | AC24: 5.5 | AD24: 67867.305
A25: 2000123 | B25: Tapa de Nalga Logs | AB25: 11934.22 | AC25: 5.5 | AD25: 65638.21
A26: 2000141 | B26: Arañita logs (pasto) | AB26: =SUM(C26:AA26) -> 0 | AC26: 4.5 | AD26: =AC26*AB26 -> 0
A27: 2000117 | B27: Pecho s/h Congelado Logs | AB27: =SUM(C27:AA27) -> 0 | AC27: 5.5 | AD27: =AC27*AB27 -> 0
A28: 2000217 | B28: Solapa de Pecho logs | AB28: 10178.4 | AC28: 5.5 | AD28: 55981.2
A29: 2000516 | B29: Bife Ancho Logs | AB29: =SUM(C29:AA29) -> 0 | AC29: 14 | AD29: =AC29*AB29 -> 0
A30: 2000531 | B30: Bife Angosto para Logs | AB30: 15.13 | AC30: 7.4 | AD30: 111.962
A31: 2000590 | B31: Trimmings 85 CL Logs en caja | AB31: 28928.28 | AC31: 5.5 | AD31: 159105.54
A32: 2000593 | B32: Tejido conectivo Logs | AB32: =SUM(C32:AA32) -> 1992.87 | AC32: 4.5 | AD32: 8967.915
A33: 2000929 | B33: Corcho de Cuadril logs | AB33: 4850.69 | AC33: 5.5 | AD33: 26678.795
A34: 4001002 | B34: Logs #F3603B | AB34: 445.5 | AD34: =AC34*AB34 -> 0
A35: 981006 | B35: Aguja - Carne sin envasar logs (congelado)
A36: 981012 | B36: Paleta - Carne sin envasar logs (congelado) | AB36: 138.69 | AC36: 6.5 | AD36: 901.485
A37: 981027 | B37: Bola de Lomo Logs - Carne sin envasar | AB37: 5933.49 | AC37: 5.5 | AD37: 32634.195
A38: 981031 | B38: B. Angosto - para beef logs (congelado) | AB38: =SUM(C38:AA38) -> 0 | AC38: 7.4 | AD38: =AC38*AB38 -> 0
A39: 981035 | B39: Matambre Block - Carne sin envasar logs (congelado) | AB39: 6857.32 | AC39: 5.5 | AD39: 37715.26
A40: 981091 | B40: Manta - Carne sin envasar logs (congelado) | AB40: =SUM(C40:AA40) -> 0 | AC40: 5.5 | AD40: =AC40*AB40 -> 0
A41: 981123 | B41: Tapa de Nalga Manta (Logs) - Carne sin envasar | AB41: 151.05 | AC41: 5.5 | AD41: 830.775
...

Sheet mano de obra
H2: T. Cambio $ | I2: 40.48
E4: 46235
E5: aportes patronales | F5: bse | G5: ag.Lic. Sv y ap.patronal | H5: prev.despido
B6: por hora | D6: más prima | E6: y cargas sociales | I6: Costo
D7: 0.53 | E7: 0.1263 | F7: 0.08546 | G7: 0.23914 | H7: 0.0125 | I7: total | J7: U$S
B8: Ofic. Esp. | C8: 188.96 | D8: =C8*$D$7+C8 -> 289.1088 | E8: =D8*$E$7 -> 36.514441 | F8: =D8*$F$7 -> 24.707238 | G8: =D8*$G$7 -> 69.137478 | H8: =D8*$H$7 -> 3.61386 | I8: =SUM(D8:H8) -> 423.08182 | J8: =I8/$I$2 -> 10.451626
B9: Oficial A | C9: 166.2 | D9: 254.286 | E9: 32.116322 | F9: 21.731282 | G9: 60.809954 | H9: 3.178575 | I9: 372.12213 | J9: 9.1927404
B10: Oficial B | C10: 156.69 | D10: 239.7357 | E10: 30.278619 | F10: 20.487813 | G10: 57.330395 | H10: 2.9966963 | I10: 350.82922 | J10: 8.6667298
B11: Medio Oficial | C11: 149.34 | D11: 228.4902 | E11: 28.858312 | F11: 19.526772 | G11: 54.641146 | H11: 2.8561275 | I11: 334.37256 | J11: 8.2601917
B12: Peón Pr | C12: 144.64 | D12: 221.2992 | E12: 27.950089 | F12: 18.91223 | G12: 52.921491 | H12: 2.76624 | I12: 323.84925 | J12: 8.0002285
B13: Peón | C13: 129.27 | D13: 197.7831 | E13: 24.980006 | F13: 16.902544 | G13: 47.297851 | H13: 2.4722888 | I13: 289.43579 | J13: 7.1500936
B14: Promedio | C14: =AVERAGE(C8:C13) -> 155.85 | D14: 238.4505 | E14: 30.116298 | F14: 20.37798 | G14: 57.023053 | H14: 2.9806313 | I14: 348.94846 | J14: 8.6202683
B17: Nestor Larrosa | E17: valor hora | G17: 417.35 | J17: =G17/I2 -> 10.31003

Sheet VNR
A3: código | B3: Producto | C3: Prec/U$S | D3: M.obra | E3: envases | F3: servicios | G3: VNR
A4: 3001 | B4: Asado 13 costillas Pasto | C4: 4.965 | D4: =-asados!AE127 -> -0.57281723 | E4: =-envases!EH23 -> -0.077069105 | F4: -0.1 | G4: =SUM(C4:F4) -> 4.2151137
B5: Asado 13 costillas s/p Pasto | C5: 4.9 | D5: =+D4 -> -0.57281723 | E5: =+E4 -> -0.077069105 | F5: =+F4 -> -0.1 | G5: 4.1501137
A6: 4000 | B6: Falda con hueso Pasto | C6: 4.6 | D6: =+D4 -> -0.57281723 | E6: =+E4 -> -0.077069105 | F6: =+F4 -> -0.1 | G6: 3.8501137
A7: 4010 | B7: Falda con hueso Grano | C7: 5.3 | D7: =+D6 -> -0.57281723 | E7: =+E6 -> -0.077069105 | F7: =+F6 -> -0.1 | G7: 4.5501137
A8: 4403 | B8: Entraña Gruesa Fresca | C8: =255.36/40.48 -> 6.3083004 | D8: =porcionados!AE304 -> -0.66282927 | E8: =-envases!AM18 -> -0.29729653 | F8: -0.1 | G8: 5.2481746
A9: 4407 | B9: Quijada | C9: 6.92 | D9: =D8 -> -0.66282927 | E9: =-envases!AH23 -> -0.22292945 | F9: =F8 -> -0.1 | G9: 5.9342413
A10: 18001830 | B10: Falda con hueso SJ - Pasto | C10: =158.03/40.48 -> 3.9039032 | D10: =+D7 -> -0.57281723 | E10: =+E7 -> -0.077069105 | F10: =+F9 -> -0.1 | G10: 3.1540168
A11: 18003350 | B11: Falda con hueso SJ - El Rancho | C11: =206.25/40.48 -> 5.0951087 | D11: =+D10 -> -0.57281723 | E11: -0.077069105 | F11: =+F10 -> -0.1 | G11: 4.3452224
A12: 3911 | B12: Asado 13 costillas Grano s/p Nirea | C12: =238.39/40.48 -> 5.889081 | D12: -0.57281723 | E12: -0.077069105 | F12: =+F11 -> -0.1 | G12: 5.1391947
A13: 3101 | B13: Asado 13 costillas Pasto s/p Nirea | C13: =208.03/40.48 -> 5.139081 | D13: -0.57281723 | E13: -0.077069105 | F13: =+F12 -> -0.1 | G13: =SUM(C13:F13) -> 4.3891947
A14: 438031 | B14: Bife Angosto Vila Congelado | C14: =870/1.1391184/40.48 -> 18.867306 | D14: =+D9 -> -0.66282927 | E14: =-envases!D148 -> -0.65727622 | F14: =+F9 -> -0.1 | G14: 17.4472
A15: 439016 | B15: Bife Ancho Vila | C15: =1160/1.1391184/40.48 -> 25.156407 | D15: =+D14 -> -0.66282927 | E15: =-envases!D64 -> -0.55706309 | F15: =+F14 -> -0.1 | G15: 23.836515
A17: NIREA
A18: 16101790 | B18: ASADO | C18: 12.61 | D18: =+D15 -> -0.66282927 | E18: =E4 -> -0.077069105 | F18: =+F15 -> -0.1 | G18: =SUM(C18:F18) -> 11.770102
A19: 16103290 | B19: ASADO 3C | C19: 12.61 | D19: =+D18 -> -0.66282927 | E19: =E4 -> -0.077069105 | F19: =+F18 -> -0.1 | G19: 11.770102
A20: 16105240 | B20: Asado nirea | C20: 12.8 | D20: -0.66282927 | E20: =E4 -> -0.077069105 | F20: -0.1 | G20: 11.960102
A21: 16601910 | B21: ASADO 5C | C21: 4.47 | D21: -0.66282927 | E21: =E4 -> -0.077069105 | F21: -0.1 | G21: 3.6301016
A22: 17001910 | B22: Asado con hueso | C22: 3.95 | D22: -0.66282927 | E22: =E4 -> -0.077069105 | F22: -0.1 | G22: 3.1101016
A23: 17071910 | B23: ASADO C/H TRASERO | C23: 4.5 | D23: -0.66282927 | E23: =E4 -> -0.077069105 | F23: -0.1 | G23: 3.6601016 | I23: =3/1.1391184/40.48 -> 0.065059674
A24: 21769820 | B24: Falda nirea ( caja) | C24: 8.2 | D24: -0.66282927 | E24: =E4 -> -0.077069105 | F24: -0.1 | G24: 7.3601016
A25: 21765230 | B25: Falda nirea Taurus | C25: 8.1 | D25: -0.66282927 | E25: =E5 -> -0.077069105 | F25: -0.1 | G25: =SUM(C25:F25) -> 7.2601016
A26: 25169820 | B26: ASADO SIN HUESO (INTERCOSTALES) | C26: 14.230015 | D26: =+D24 -> -0.66282927 | E26: =E4 -> -0.077069105 | F26: =+F24 -> -0.1 | G26: 13.390117
A27: 18961511 | B27: Pecho Nirea (bins) | C27: =193.75/40.48 -> 4.7863142 | D27: -0.66282927 | E27: =E5 -> -0.077069105 | F27: -0.1 | G27: 3.9464159

Sheet envases
D1: 46216 | E1: dólar 13/07/26 | J1: =E1 -> dólar 13/07/26 | O1: =J1 -> dólar 13/07/26 | T1: =O1 -> dólar 13/07/26 | Y1: =T1 -> dólar 13/07/26 | AD1: =Y1 -> dólar 13/07/26 | AI1: =AD1 -> dólar 13/07/26
B2: 438/439 | E2: 40.26 | G2: 437 | J2: =E2 -> 40.26 | L2: 436 | O2: =J2 -> 40.26 | Q2: 998 | T2: =O2 -> 40.26 | V2: 993 | Y2: =T2 -> 40.26 | AA2: 991 | AD2: =Y2 -> 40.26 | AF2: 884 | AI2: =AD2 -> 40.26 | AK2: 1987 | AP2: 3673 | AU2: 5687036 | AZ2: 4410 UMI | BE2: 442 / 443 RANCHO | BJ2: 13390 | BO2: 3516 | BT2: 4516 | BY2: 4543 | CD2: 4545 | CI2: 4546 | CN2: 4858 | CS2: 6172 / 6173 | CX2: 3193 | DC2: 4841 | DH2: 5516 | DM2: 1993 | DR2: 6112 | DW2: 2366
D3: Precio UYU | E3: Precio U$S | I3: Precio UYU | J3: Precio U$S | N3: Precio UYU | O3: Precio U$S
B4: 439010 | C4: Envase Chuck | D4: 490 | E4: =D4/E2 -> 12.170889 | G4: 437016 | H4: Envase Bife Ancho | I4: 1105 | J4: =I4/E2 -> 27.446597 | L4: 436031 | M4: Envase Bife Angosto 3,5 - 4 kg | N4: 447 | O4: =N4/E2 -> 11.102832 | Q4: 998001 | R4: Envase Delantero C/H | V4: 993170 | W4: Envase Entraña fina (6x paquete) | AA4: 991072 | AB4: Envase Entraña gruesa (2x paquete) | AF4: 884507 | AG4: Quijada CC - (Maseteros) / Cheek Meat | AK4: 1987072 | AL4: Envase Entraña gruesa (2x paquete) GF | AP4: 3673916 | AQ4: Envase Bife Ancho Porcionado | AU4: 5687036 | AV4: Envase Carne Picada | AZ4: 441024 | BA4: Envasado Colita de Cuadril | BE4: 442024 | BF4: Envasado Colita de Cuadril EL RANCHO | BJ4: 13390 | BK4: Envase Trimming Angus 80CL | BO4: 3516360 | BP4: Envasado Asado s/h 3c UMI | BT4: 4516093 | BU4: Envasado Intercostales Cortos Taurus | BY4: 4543760 | BZ4: Envasado Asado 7c 2 tiras Vila | CD4: 4545160 | CE4: Envase Asado 1/C UMI | CI4: 4546960 | CJ4: Envasado Asado S/H Ink | CN4: 4858160 | CO4: Envase Asado 1/C Vila Brasil | CS4: 4865160 | CT4: Envase Asado 1/C Vila Brasil | CX4: 3193072 | CY4: Envase Entraña gruesa (grass) | DC4: 4841024 | DD4: Envase Colita de Cuadril - Maminha | DH4: 5516193 | DI4: Envase Intercostales Largos INK | DM4: 1993916 | DN4: Envasado Bife Ancho TG Porcionado | DR4: 6112716 | DS4: Envase Bife Ancho | DW4: 2366095 | DX4: Envase Cubos | EF4: Envase Logs | EI4: Código | EJ4: Asado Pasto a 5 y 8 costillas China | EK4: Cantidad | EL4: Precio U$S
B5: Código | C5: Insumos | D5: Precio U$S | G5: Código | H5: Insumos | I5: Precio U$S | L5: Código | M5: Insumos | N5: Precio U$S | Q5: Código | R5: Insumos | S5: Precio U$S | V5: Código | W5: Insumos | X5: Precio U$S | AA5: Código | AB5: Insumos | AC5: Precio U$S | AF5: Código | AG5: Insumos | AH5: Precio U$S | AK5: Código | AL5: Insumos | AM5: Precio U$S | AP5: Código | AQ5: Insumos | AR5: Precio U$S | AU5: Código | AV5: Insumos | AW5: Precio U$S | AZ5: Código | BA5: Insumos | BB5: Precio U$S | BE5: Código | BF5: Insumos | BG5: Precio U$S | BJ5: Código | BK5: Insumos | BL5: Precio U$S | BO5: Código | BP5: Insumos | BQ5: Precio U$S | BT5: Código | BU5: Insumos | BV5: Precio U$S | BY5: Código | BZ5: Insumos | CA5: Precio U$S | CD5: Código | CE5: Insumos | CF5: Precio U$S | CI5: Código | CJ5: Insumos | CK5: Precio U$S | CN5: Código | CO5: Insumos | CP5: Precio U$S | CS5: Código | CT5: Insumos | CU5: Precio U$S | CX5: Código | CY5: Insumos | CZ5: Precio U$S | DC5: Código | DD5: Insumos | DE5: Precio U$S | DH5: Código | DI5: Insumos | DJ5: Precio U$S | DM5: Código | DN5: Insumos | DO5: Precio U$S | DR5: Código | DS5: Insumos | DT5: Precio U$S | DW5: Código | DX5: Insumos | DY5: Precio U$S | EE5: Código | EF5: Insumo | EG5: Precio U$S | EI5: 2037 | EJ5: Tapa | EK5: 1 | EL5: =insumos!H268 -> 0.65
C6: Envasado | H6: Envasado | M6: Envasado | R6: Envasado | W6: Envasado | AB6: Envasado | AG6: Envasado | AL6: Envasado | AQ6: Envasado | AV6: Envasado | BA6: Envasado | BF6: Envasado | BK6: Envasado | BP6: Envasado | BU6: Envasado | BZ6: Envasado | CE6: Envasado | CJ6: Envasado | CO6: Envasado | CT6: Envasado | CY6: Envasado | DD6: Envasado | DI6: Envasado | DN6: Envasado | DS6: Envasado | DX6: Envasado | EF6: 1 pallets fumigado | EG6: =512.4/40.48 -> 12.658103 | EI6: 6184 | EJ6: Fondo | EK6: 1 | EL6: =insumos!H215 -> 0.6
B7: 3741 | C7: Fondo Cofre | D7: =insumos!$G$213 -> 0.83558719 | G7: 5524 | H7: FONDO ENFRIADO (nueva medida) 505x380x155 cm - MERCOPACK | I7: =insumos!$H$217 -> 0.895 | L7: 3741 | M7: Fondo Cofre | N7: =insumos!$G$213 -> 0.83558719 | Q7: 6184 | R7: Fondo Congelado | S7: =insumos!$H$215 -> 0.6 | V7: 6184 | W7: Fondo Congelado | X7: =insumos!$H$215 -> 0.6 | AA7: 3741 | AB7: Fondo Cofre | AC7: =insumos!$G$213 -> 0.83558719 | AF7: 2055 | AG7: Tapa blanca enfriado | AH7: =insumos!$H$266 -> 1.15 | AK7: 3741 | AL7: Fondo cofre | AM7: =insumos!$G$213 -> 0.83558719 | AP7: 5524 | AQ7: FONDO ENFRIADO (nueva medida) 505x380x155 cm - MERCOPACK | AR7: =insumos!$H$217 -> 0.895 | AU7: 6184 | AV7: Fondo Congelado | AW7: =insumos!$H$215 -> 0.6 | AZ7: 3741 | BA7: Fondo Cofre | BB7: =insumos!$G$213 -> 0.83558719 | BE7: 3741 | BF7: Fondo Cofre | BG7: =insumos!$G$213 -> 0.83558719 | BJ7: 6184 | BK7: Fondo Congelado | BL7: =insumos!$H$215 -> 0.6 | BO7: 3741 | BP7: Fondo Cofre | BQ7: =insumos!$G$213 -> 0.83558719 | BT7: 3741 | BU7: Fondo Cofre | BV7: =insumos!$G$213 -> 0.83558719 | BY7: 6184 | BZ7: Fondo Congelado | CA7: =insumos!$H$215 -> 0.6 | CD7: 3741 | CE7: Fondo Cofre | CF7: =insumos!$G$213 -> 0.83558719 | CI7: 3741 | CJ7: Fondo Cofre | CK7: =insumos!$G$213 -> 0.83558719 | CN7: 3741 | CO7: Fondo Cofre | CP7: =insumos!$G$213 -> 0.83558719 | CS7: 3741 | CT7: Fondo Cofre | CU7: =insumos!$G$213 -> 0.83558719 | CX7: 3741 | CY7: Fondo Cofre | CZ7: =insumos!$G$213 -> 0.83558719 | DC7: 3741 | DD7: Fondo Cofre | DE7: =insumos!$G$213 -> 0.83558719 | DH7: 3741 | DI7: Fondo Cofre | DJ7: =insumos!$G$213 -> 0.83558719 | DM7: 3741 | DN7: Fondo Cofre | DO7: =insumos!$G$213 -> 0.83558719 | DR7: 5524 | DS7: FONDO ENFRIADO (nueva medida) 505x380x155 cm - MERCOPACK | DT7: =insumos!$H$217 -> 0.895 | DW7: 5524 | DX7: FONDO ENFRIADO (nueva medida) 505x380x155 cm - MERCOPACK | DY7: =insumos!$H$217 -> 0.895 | EE7: 6261 | EF7: 1 caja octogonal | EG7: =insumos!H99 -> 12.25 | EI7: 4542 | EJ7: Bolsa 95 x 60 | EK7: 1 | EL7: =insumos!I35 -> 0.022058824
B8: 3759 | C8: TAPA VILA COFRE 156 (135)(gris) - Mpack | D8: =+insumos!$G$284 -> 1.1352417 | G8: 5523 | H8: TAPA VILA gris - 50x38x15.5 cm (nueva medida) - Mercopack | I8: =+insumos!$H$285 -> 1.1829611 | L8: 3806 | M8: TAPA BLANCA COFRE 135 - doble micro - MERCOPACK | N8: =+insumos!$H$267 -> 1.2 | Q8: 2037 | R8: Tapa blanca congelado | S8: =+insumos!$H$268 -> 0.65 | V8: 2037 | W8: Tapa blanca congelado | X8: =+insumos!$H$268 -> 0.65 | AA8: 3806 | AB8: TAPA BLANCA COFRE 135 - doble micro - MERCOPACK | AC8: =+insumos!$H$267 -> 1.2 | AF8: 5524 | AG8: Fondo enfriado (nueva medida) 505x380x155 cm – MERCOPACK | AH8: =insumos!$H$217 -> 0.895 | AK8: 3759 | AL8: TAPA VILA COFRE 156 (135)(gris) - Mpack | AM8: =+insumos!$G$284 -> 1.1352417 | AP8: 5523 | AQ8: TAPA VILA gris - 50x38x15.5 cm (nueva medida) - Mercopack | AR8: =+insumos!$H$285 -> 1.1829611 | AU8: 2055 | AV8: TAPA BLANCA 136 (cartulina)- Mpack | AW8: =+insumos!$H$266 -> 1.15 | AZ8: 5653 | BA8: TAPA UMi CONGELADO (136) - IMPRIMEX | BB8: =+insumos!$G$283 -> 1.1 | BE8: 6287 | BF8: TAPA 135 COFRE EL RANCHO - IMPRIMEX | BG8: =+insumos!$H$263 -> 1.6 | BJ8: 2037 | BK8: Tapa blanca congelado | BL8: =+insumos!$H$268 -> 0.65 | BO8: 5653 | BP8: TAPA UMi CONGELADO (136) - IMPRIMEX | BQ8: =+insumos!$G$283 -> 1.1 | BT8: 6265 | BU8: TAPA TAURUS BIFE ONTILCOR - MERCOPACK | BV8: =+insumos!$H$279 -> 1.25 | BY8: 5523 | BZ8: TAPA VILA gris - 50x38x15.5 cm (nueva medida) - Mercopack | CA8: =+insumos!$H$285 -> 1.1829611 | CD8: 5653 | CE8: TAPA UMi CONGELADO (136) - IMPRIMEX | CF8: =+insumos!$G$283 -> 1.1 | CI8: 5251 | CJ8: TAPA INK COFRE - IMPRIMEX | CK8: =+insumos!$H$274 -> 1.6 | CN8: 3759 | CO8: TAPA VILA COFRE 156 (135)(gris) - Mpack | CP8: =+insumos!$G$284 -> 1.1352417 | CS8: 3759 | CT8: TAPA VILA COFRE 156 (135)(gris) - Mpack | CU8: =+insumos!$G$284 -> 1.1352417 | CX8: 3806 | CY8: TAPA BLANCA COFRE 135 - doble micro - MERCOPACK | CZ8: =+insumos!$H$267 -> 1.2 | DC8: 3759 | DD8: TAPA VILA gris - 50x38x15.5 cm (nueva medida) - Mercopack | DE8: =+insumos!$G$284 -> 1.1352417 | DH8: 5251 | DI8: TAPA INK COFRE - IMPRIMEX | DJ8: =+insumos!$H$274 -> 1.6 | DM8: 6265 | DN8: TAPA TAURUS BIFE ONTILCOR - MERCOPACK | DO8: =+insumos!$H$279 -> 1.25 | DR8: 2055 | DS8: TAPA BLANCA 136 (cartulina)- Mpack | DT8: =+insumos!$H$266 -> 1.15 | DW8: 2055 | DX8: TAPA BLANCA 136 (cartulina)- Mpack | DY8: =+insumos!$H$266 -> 1.15 | EE8: 6286 | EF8: 1 sobre tapa | EG8: =+insumos!H256 -> 1.24 | EI8: 3817 | EJ8: Cinta adhesiva ( metros) | EK8: 1.8 | EL8: =insumos!I103*1.8 -> 0.02088
B9: 4653 | C9: SEPARADORES 530X290 – MERCOPACK | D9: =insumos!$H$254*3 -> 0.55921788 | E9: 3 unid. X caja | G9: 4542 | H9: Bolsa 95X60 | I9: =insumos!$I$35 -> 0.022058824 | L9: 4541 | M9: Bolsa 85x60 | N9: =insumos!$H$43 -> 0.022058824 | Q9: 4542 | R9: Bolsa 95X60 | S9: =insumos!$I$35 -> 0.022058824 | V9: 4542 | W9: Bolsa 95X60 | X9: =insumos!$I$35 -> 0.022058824 | AA9: 4541 | AB9: Bolsa 85x60 | AC9: =insumos!$H$43 -> 0.022058824 | AF9: 4542 | AG9: Bolsa 95X60 | AH9: =insumos!$I$35 -> 0.022058824 | AK9: 4541 | AL9: Bolsa 85X60 | AM9: =insumos!$H$43 -> 0.022058824 | AP9: 4986 | AQ9: SEPARADORES 570x230 mm - MERCOPACK | AR9: =insumos!$H$255*3 -> 0.56999964 | AS9: 3 unid. X caja | AU9: 4986 | AV9: SEPARADORES 570x230 mm - MERCOPACK | AW9: =insumos!$H$255*4 -> 0.75999952 | AX9: 4 unid. X caja | AZ9: 4653 | BA9: SEPARADORES 530X290 – MERCOPACK | BB9: =insumos!$H$254*2 -> 0.37281192 | BC9: 2 unid. X caja | BE9: 4653 | BF9: SEPARADORES 530X290 – MERCOPACK | BG9: =insumos!$H$254*2 -> 0.37281192 | BH9: 2 unid. X caja | BJ9: 2105 | BK9: BOLSA 80 (60) x 75 /ø80 AZUL, impresa EN ROLLO - STRONG | BL9: =insumos!$I$33 -> 0.049999554 | BO9: 4653 | BP9: SEPARADORES 530X290 – MERCOPACK | BQ9: =insumos!$H$254 -> 0.18640596 | BY9: 4542 | BZ9: Bolsa 95X60 | CA9: =insumos!$I$35 -> 0.022058824 | CD9: 4653 | CE9: SEPARADORES 530X290 – MERCOPACK | CF9: =insumos!$H$254 -> 0.18640596 | CI9: 4653 | CJ9: SEPARADORES 530X290 – MERCOPACK | CK9: =insumos!$H$254*3 -> 0.55921788 | CL9: 3 unid. X caja | CN9: 4653 | CO9: SEPARADORES 530X290 – MERCOPACK | CP9: =insumos!$H$254 -> 0.18640596 | CS9: 4653 | CT9: SEPARADORES 530X290 – MERCOPACK | CU9: =insumos!$H$254 -> 0.18640596 | CX9: 4541 | CY9: Bolsa 85x60 | CZ9: =insumos!$H$43 -> 0.022058824 | DC9: 4653 | DD9: SEPARADORES 530X290 – MERCOPACK | DE9: =insumos!$H$254*3 -> 0.55921788 | DF9: 3 unid. X caja | DH9: 4541 | DI9: Bolsa 85x60 | DJ9: =insumos!$H$43 -> 0.022058824 | DM9: 4653 | DN9: SEPARADORES 530X290 – MERCOPACK | DO9: =insumos!$H$254*3 -> 0.55921788 | DP9: 3 unid. X caja | DR9: 4542 | DS9: Bolsa 95X60 | DT9: =insumos!$I$35 -> 0.022058824 | DW9: 4542 | DX9: Bolsa 95X60 | DY9: =insumos!$I$35 -> 0.022058824 | EE9: 6262 | EF9: 1 tapa | EG9: 2.18 | EI9: 2173 | EJ9: Fajas | EK9: 2 | EL9: =+insumos!H149*2 -> 0.034950266
B10: 4541 | C10: Bolsa 85x60 | D10: =insumos!$H$43 -> 0.022058824 | G10: 3817 | H10: Cinta adhesiva ( metros) | I10: =insumos!$I$103*1.8 -> 0.02088 | J10: 1,8 metros | L10: 3817 | M10: Cinta adhesiva ( metros) | N10: =insumos!$I$103*1.8 -> 0.02088 | O10: 1,8 metros | Q10: 3817 | R10: Cinta adhesiva ( metros) | S10: =insumos!$I$103*1.8 -> 0.02088 | T10: 1.8 metros | V10: 3817 | W10: Cinta adhesiva ( metros) | X10: =insumos!$I$103*1.8 -> 0.02088 | Y10: 1.8 metros | AA10: 3817 | AB10: Cinta adhesiva ( metros) | AC10: =insumos!$I$103*1.8 -> 0.02088 | AD10: 1.8 metros | AF10: 3817 | AG10: Cinta adhesiva ( metros) | AH10: =insumos!I103*1.8 -> 0.02088 | AI10: 1,8 metros | AK10: 3817 | AL10: Cinta adhesiva ( metros) | AM10: =insumos!$I$103*1.8 -> 0.02088 | AN10: 1.8 metros | AP10: 4542 | AQ10: Bolsa 95X60 | AR10: =insumos!$I$35 -> 0.022058824 | AU10: 4542 | AV10: Bolsa 95X60 | AW10: =insumos!$I$35 -> 0.022058824 | AZ10: 5315 | BA10: BOLSA COFRE 85(60)X46/ø40, impr. en rollo, ROSADA - STRONG | BB10: =insumos!$H$45 -> 0.028 | BE10: 6280 | BF10: BOLSA NARANJA 85(60)X46/40 - STRONG | BG10: =insumos!$H$50 -> 0.027941176 | BJ10: 3817 | BK10: Cinta adhesiva ( metros) | BL10: =insumos!$I$103*1.8 -> 0.02088 | BM10: 1.8 metros | BO10: 5315 | BP10: BOLSA COFRE 85(60)X46/ø40, impr. en rollo, ROSADA - STRONG | BQ10: =insumos!$H$45 -> 0.028 | BT10: 5353 | BU10: BOLSA COFRE 85(60)X46/ø40, impr. en rollo, AMARILLA - STRONG | BV10: =insumos!$H$44 -> 0.028 | BY10: 4986 | BZ10: SEPARADORES 570x230 mm - MERCOPACK | CA10: =insumos!$H$255*4 -> 0.75999952 | CB10: 4 unid. X caja | CD10: 5315 | CE10: BOLSA COFRE 85(60)X46/ø40, impr. en rollo, ROSADA - STRONG | CF10: =insumos!$H$45 -> 0.028 | CI10: 4541 | CJ10: Bolsa 85X60 | CK10: =insumos!$H$43 -> 0.022058824 | CN10: 4541 | CO10: Bolsa 85X60 | CP10: =insumos!$H$43 -> 0.022058824 | CS10: 4541 | CT10: Bolsa 85X60 | CU10: =insumos!$H$43 -> 0.022058824 | CX10: 3817 | CY10: Cinta adhesiva ( metros) | CZ10: =insumos!$I$103*1.8 -> 0.02088 | DA10: 1,8 metros | DC10: 4541 | DD10: Bolsa 85X60 | DE10: =insumos!$H$43 -> 0.022058824 | DH10: 3817 | DI10: Cinta adhesiva ( metros) | DJ10: =insumos!$I$103*1.8 -> 0.02088 | DK10: 1.8 metros | DM10: 5353 | DN10: BOLSA COFRE 85(60)X46/ø40, impr. en rollo, AMARILLA - STRONG | DO10: =insumos!$H$44 -> 0.028 | DR10: 3817 | DS10: Cinta adhesiva ( metros) | DT10: =insumos!$I$103*1.8 -> 0.02088 | DU10: 1,8 metros | DW10: 3817 | DX10: Cinta adhesiva ( metros) | DY10: =insumos!$I$103*1.8 -> 0.02088 | DZ10: 1,8 metros | EE10: 5383 | EF10: 1 bolsa de huesos china | EG10: 0.0168 | EI10: 2923 | EJ10: Film Strechs (0,160 kls.p/pallets) | EL10: =+insumos!I202*0.16 -> 0.09
B11: 3817 | C11: Cinta adhesiva ( metros) | D11: =insumos!$I$103*1.8 -> 0.02088 | E11: 1,8 metros | G11: 2173 | H11: Fajas | I11: =+insumos!$H$149*2 -> 0.034950266 | J11: 2 unidades | L11: 2173 | M11: Fajas | N11: =+insumos!$H$149*2 -> 0.034950266 | O11: 2 unidades | Q11: 2173 | R11: Fajas | S11: =+insumos!$H$149*2 -> 0.034950266 | T11: 2 unidades | V11: 2173 | W11: Fajas | X11: =+insumos!$H$149*2 -> 0.034950266 | Y11: 2 unidades | AA11: 2173 | AB11: Fajas | AC11: =+insumos!$H$149*2 -> 0.034950266 | AD11: 2 unidades | AF11: 2173 | AG11: Fajas | AH11: =+insumos!H149*2 -> 0.034950266 | AI11: 2 unidades | AK11: 2173 | AL11: Fajas | AM11: =+insumos!$H$149*2 -> 0.034950266 | AN11: 2 unidades | AP11: 3817 | AQ11: Cinta adhesiva ( metros) | AR11: =insumos!$I$103*1.8 -> 0.02088 | AS11: 1,8 metros | AU11: 3817 | AV11: Cinta adhesiva ( metros) | AW11: =insumos!$I$103*1.8 -> 0.02088 | AX11: 1,8 metros | AZ11: 3817 | BA11: Cinta adhesiva ( metros) | BB11: =insumos!$I$103*1.8 -> 0.02088 | BC11: 1,8 metros | BE11: 3817 | BF11: Cinta adhesiva ( metros) | BG11: =insumos!$I$103*1.8 -> 0.02088 | BH11: 1,8 metros | BJ11: 2173 | BK11: Fajas | BL11: =+insumos!$H$149*2 -> 0.034950266 | BM11: 2 unidades | BO11: 3817 | BP11: Cinta adhesiva ( metros) | BQ11: =insumos!$I$103*1.8 -> 0.02088 | BR11: 1,8 metros | BT11: 3817 | BU11: Cinta adhesiva ( metros) | BV11: =insumos!$I$103*1.8 -> 0.02088 | BW11: 1,8 metros | BY11: 3817 | BZ11: Cinta adhesiva ( metros) | CA11: =insumos!$I$103*1.8 -> 0.02088 | CB11: 1.8 metros | CD11: 3817 | CE11: Cinta adhesiva ( metros) | CF11: =insumos!$I$103*1.8 -> 0.02088 | CG11: 1.8 metros | CI11: 3817 | CJ11: Cinta adhesiva ( metros) | CK11: =insumos!$I$103*1.8 -> 0.02088 | CL11: 1.8 metros | CN11: 3817 | CO11: Cinta adhesiva ( metros) | CP11: =insumos!$I$103*1.8 -> 0.02088 | CQ11: 1.8 metros | CS11: 3817 | CT11: Cinta adhesiva ( metros) | CU11: =insumos!$I$103*1.8 -> 0.02088 | CV11: 1.8 metros | CX11: 2173 | CY11: Fajas | CZ11: =+insumos!$H$149*2 -> 0.034950266 | DA11: 2 unidades | DC11: 3817 | DD11: Cinta adhesiva ( metros) | DE11: =insumos!$I$103*1.8 -> 0.02088 | DF11: 1.8 metros | DH11: 2173 | DI11: Fajas | DJ11: =+insumos!$H$149*2 -> 0.034950266 | DK11: 2 unidades | DM11: 3817 | DN11: Cinta adhesiva ( metros) | DO11: =insumos!$I$103*1.8 -> 0.02088 | DP11: 1,8 metros | DR11: 2173 | DS11: Fajas | DT11: =+insumos!$H$149*2 -> 0.034950266 | DU11: 2 unidades | DW11: 2173 | DX11: Fajas | DY11: =+insumos!$H$149*2 -> 0.034950266 | DZ11: 2 unidades | EE11: 2173 | EF11: Faja Numerada | EG11: 0.0167 | EI11: 2445 | EJ11: Pallets ( 30 cajas de 20 kls) | EK11: 1 | EL11: =(440/40.48)/(30*20) -> 0.018115942
B12: 2173 | C12: Fajas | D12: =+insumos!$H$149*2 -> 0.034950266 | E12: 2 unidades | G12: 3636 | H12: Etiqueta Caja | I12: =+insumos!$H$121 -> 0.0445 | L12: 3636 | M12: Etiqueta Caja | N12: =+insumos!$H$121 -> 0.0445 | Q12: 3636 | R12: Etiqueta Caja | S12: =+insumos!$H$121 -> 0.0445 | V12: 3636 | W12: Etiqueta Caja | X12: =+insumos!$H$121 -> 0.0445 | AA12: 3636 | AB12: Etiqueta Caja | AC12: =+insumos!$H$121 -> 0.0445 | AF12: 3636 | AG12: Etiqueta Caja | AH12: =+insumos!H121 -> 0.0445 | AK12: 3636 | AL12: Etiqueta Caja | AM12: =+insumos!$H$121 -> 0.0445 | AP12: 2173 | AQ12: Fajas | AR12: =+insumos!$H$149*2 -> 0.034950266 | AS12: 2 unidades | AU12: 2173 | AV12: Fajas | AW12: =+insumos!$H$149*2 -> 0.034950266 | AX12: 2 unidades | AZ12: 2173 | BA12: Fajas | BB12: =+insumos!$H$149*2 -> 0.034950266 | BC12: 2 unidades | BE12: 2173 | BF12: Fajas | BG12: =+insumos!$H$149*2 -> 0.034950266 | BH12: 2 unidades | BJ12: 3636 | BK12: Etiqueta Caja | BL12: =+insumos!$H$121 -> 0.0445 | BO12: 2173 | BP12: Fajas | BQ12: =+insumos!$H$149*2 -> 0.034950266 | BR12: 2 unidades | BT12: 2173 | BU12: Fajas | BV12: =+insumos!$H$149*2 -> 0.034950266 | BW12: 2 unidades | BY12: 2173 | BZ12: Fajas | CA12: =+insumos!$H$149*2 -> 0.034950266 | CB12: 2 unidades | CD12: 2173 | CE12: Fajas | CF12: =+insumos!$H$149*2 -> 0.034950266 | CG12: 2 unidades | CI12: 2173 | CJ12: Fajas | CK12: =+insumos!$H$149*2 -> 0.034950266 | CL12: 2 unidades | CN12: 2173 | CO12: Fajas | CP12: =+insumos!$H$149*2 -> 0.034950266 | CQ12: 2 unidades | CS12: 2173 | CT12: Fajas | CU12: =+insumos!$H$149*2 -> 0.034950266 | CV12: 2 unidades | CX12: 3636 | CY12: Etiqueta Caja | CZ12: =+insumos!$H$121 -> 0.0445 | DC12: 2173 | DD12: Fajas | DE12: =+insumos!$H$149*2 -> 0.034950266 | DF12: 2 unidades | DH12: 3636 | DI12: Etiqueta Caja | DJ12: =+insumos!$H$121 -> 0.0445 | DM12: 2173 | DN12: Fajas | DO12: =+insumos!$H$149*2 -> 0.034950266 | DP12: 2 unidades | DR12: 3636 | DS12: Etiqueta Caja | DT12: =+insumos!$H$121 -> 0.0445 | DW12: 3636 | DX12: Etiqueta Caja | DY12: =+insumos!$H$121 -> 0.0445 | EE12: 6268 | EF12: 35 mts. Fleje | EG12: =0.0245*35 -> 0.8575 | EI12: 2119 | EJ12: Hoja separador | EK12: 2 | EL12: =insumos!I224*2 -> 0
B13: 3636 | C13: Etiqueta Caja | D13: =+insumos!$H$121 -> 0.0445 | H13: Paquete | M13: Paquete | R13: Paquete | W13: Paquete | AB13: Paquete | AG13: Paquete | AL13: Paquete | AP13: 3636 | AQ13: Etiqueta Caja | AR13: =+insumos!$H$121 -> 0.0445 | AU13: 3636 | AV13: Etiqueta Caja | AW13: =+insumos!$H$121 -> 0.0445 | AZ13: 3636 | BA13: Etiqueta Caja | BB13: =+insumos!$H$121 -> 0.0445 | BE13: 3636 | BF13: Etiqueta Caja | BG13: =+insumos!$H$121 -> 0.0445 | BK13: Paquete | BO13: 3636 | BP13: Etiqueta Caja | BQ13: =+insumos!$H$121 -> 0.0445 | BT13: 3636 | BU13: Etiqueta Caja | BV13: =+insumos!$H$121 -> 0.0445 | BY13: 3636 | BZ13: Etiqueta Caja | CA13: =+insumos!$H$121 -> 0.0445 | CD13: 3636 | CE13: Etiqueta Caja | CF13: =+insumos!$H$121 -> 0.0445 | CI13: 3636 | CJ13: Etiqueta Caja | CK13: =+insumos!$H$121 -> 0.0445 | CN13: 3636 | CO13: Etiqueta Caja | CP13: =+insumos!$H$121 -> 0.0445 | CS13: 3636 | CT13: Etiqueta Caja | CU13: =+insumos!$H$121 -> 0.0445 | CY13: Paquete | DC13: 3636 | DD13: Etiqueta Caja | DE13: =+insumos!$H$121 -> 0.0445 | DI13: Paquete | DM13: 3636 | DN13: Etiqueta Caja | DO13: =+insumos!$H$121 -> 0.0445 | DS13: Paquete | DX13: Paquete | EE13: 3108 | EF13: 160 grms film | EG13: 0.24 | EI13: 2157 | EJ13: Rotulo bopp term 50 x 40 | EK13: 1 | EL13: =insumos!H249 -> 0.0085
C14: Paquete | G14: 6259 | H14: BOBINA 280x650 MM IMP VILA - MERCOPACK | I14: =insumos!$H$23*4 -> 1.1519995 | J14: 4 unid. X caja | L14: 5214 | M14: BOLSA VACIO 18X67 SOLDA V SB15- MERCOPACK | N14: =insumos!$H$65*3 -> 0.41399939 | O14: 3 unid. X caja | V14: 4745 | W14: Bolsa 31x40 | X14: =insumos!H93*8 -> 0.912 | Y14: 8 unid. X caja | AA14: 4741 | AB14: Bolsa 20x50 | AC14: =insumos!$H$90*10 -> 3.08 | AD14: 10 unid. X caja | AF14: 5138 | AG14: Etiqueta 102x78 Bopp Term | AH14: =insumos!H113*4 -> 0.10803782 | AI14: 4 unid. X caja | AK14: 6293 | AL14: Bolsa 20x50 Vila | AM14: =insumos!$H$55*10 -> 1.61 | AN14: 10 unid. X caja | AQ14: Paquete | AV14: Paquete | BA14: Paquete | BF14: Paquete | BP14: Paquete | BU14: Paquete | BZ14: Paquete | CE14: Paquete | CJ14: Paquete | CO14: Paquete | CT14: Paquete | CX14: 4741 | CY14: Bolsa 20x50 | CZ14: =insumos!$H$90*10 -> 3.08 | DA14: 10 unid. X caja | DD14: Paquete | DH14: 5138 | DI14: ET. BOPP TERM. 102X78 - RR | DJ14: =insumos!$H$113*12 -> 0.32411345 | DK14: 12 unid. X caja | DN14: Paquete | DR14: 5214 | DS14: BOLSA VACIO 18X67 SOLDA V SB15- MERCOPACK | DT14: =insumos!$H$65*4 -> 0.55199919 | DU14: 4 unid. X caja | DW14: 4741 | DX14: BOLSA VACIO IMP. 20X50 - MERCOPACK | DY14: =insumos!$H$90*12 -> 3.696 | DZ14: 12 unid. X caja | EE14: 2122 | EF14: bolsa celeste | EG14: =0.0583333333333333*45 -> 2.625 | EI14: 3636 | EJ14: Etqiueta bopp termico 100 x 154 lisa RR | EK14: 1 | EL14: =insumos!H121 -> 0.0445
B15: 6269 | C15: Etiqueta delantera | D15: =insumos!H150*12 -> 1.1319 | E15: 12 unid. X caja | G15: 5138 | H15: ET. BOPP TERM. 102X78 - RR | I15: =insumos!$H$113*4 -> 0.10803782 | J15: 4 unid. X caja | L15: 5138 | M15: ET. BOPP TERM. 102X78 - RR | N15: =insumos!$H$113*3 -> 0.081028362 | O15: 3 unid. X caja | R15: Total | S15: =SUM(S7:S14) -> 1.3723891 | W15: Total | X15: =SUM(X7:X14) -> 2.2843891 | AA15: 3887 | AB15: ET. BOPP TERMICO 100x050 LISA - RR | AC15: =insumos!$H$120*10 -> 0.199 | AD15: 10 unid. X caja | AF15: 4745 | AG15: Bolsa 31x40 | AH15: =insumos!H93*4 -> 0.456 | AI15: 4 unid. X caja | AL15: Total | AM15: =SUM(AM7:AM14) -> 3.7032179 | AP15: 4102 | AQ15: Etiqueta Trasera 100x100 | AR15: =insumos!$H$115*28 -> 0.924 | AS15: 28 unid. X caja | AU15: 6290 | AV15: Etiqueta delantera | AW15: =insumos!H190*35 -> 1.82 | AX15: 35 unid. X caja | AZ15: 4102 | BA15: Etiqueta Trasera 100x100 | BB15: =insumos!$H$115*9 -> 0.297 | BC15: 9 unid. X caja | BE15: 5138 | BF15: ET. BOPP TERM. 102X78 - RR | BG15: =insumos!$H$113*12 -> 0.32411345 | BH15: 12 unid. X caja | BO15: 4102 | BP15: Etiqueta Trasera 100x100 | BQ15: =insumos!$H$115*4 -> 0.132 | BR15: 4 unid. X caja | BT15: 5138 | BU15: ET. BOPP TERM. 102X78 - RR | BV15: =insumos!$H$113*12 -> 0.32411345 | BW15: 12 unid. X caja | CD15: 5138 | CE15: ET. BOPP TERM. 102X78 - RR | CF15: =insumos!$H$113*16 -> 0.43215126 | CG15: 16 unid. X caja | CI15: 5214 | CJ15: BOLSA VACIO 18X67 SOLDA V SB15- MERCOPACK | CK15: =insumos!$H$65*8 -> 1.1039984 | CN15: 6216 | CO15: ETIQUETAS BOPP MET.DOBLE CAPA 084X081 - ASADO 1 COSTILLA CONGELADO | CP15: =insumos!$H$181*16 -> 1.568 | CQ15: 16 unid. X caja | CS15: 6216 | CT15: ETIQUETAS BOPP MET.DOBLE CAPA 084X081 - ASADO 1 COSTILLA CONGELADO | CU15: =insumos!$H$181*16 -> 1.568 | CV15: 16 unid. X caja | DC15: 6206 | DD15: Etiqueta delantera | DE15: =insumos!$H$186*12 -> 1.1007317 | DF15: 12 unid. X caja | DH15: 5250 | DI15: Et. INK OPP - 7.2X14 - IMPRIMEX | DJ15: =insumos!H131*12 -> 0.9 | DK15: 12 unid. X caja | DW15: 5138 | DX15: ET. BOPP TERM. 102X78 - RR | DY15: =insumos!$H$113*12 -> 0.32411345 | DZ15: 12 unid. X caja | EF15: Total | EG15: =SUM(EG6:EG14) -> 32.084103 | EJ15: Total por Caja | EL15: =SUM(EL5:EL14) -> 1.489005
B16: 5202 | C16: Etiqueta Trasera | D16: =insumos!$H$114*16 -> 0.42151619 | E16: 12 unid. X caja | H16: Total | I16: =SUM(I7:I15) -> 3.4603875 | M16: Total | N16: =SUM(N7:N15) -> 2.653004 | R16: peso prom. Caja | S16: =1558.78/83 -> 18.780482 | W16: peso prom. Caja | X16: 20.39 | AB16: Total | AC16: =SUM(AC7:AC15) -> 5.4369763 | AL16: peso prom. Caja | AM16: 12.83 | AP16: 6229 | AQ16: TAPA BARRERA NEGRA 250 C (FILM PARA TERMOFORMADORA) - MULTIPACK DIAMALER | AR16: =insumos!$I$265*28 -> 0.60259547 | AS16: 28 unid. X caja | AZ16: 6229 | BA16: TAPA BARRERA NEGRA 250 C (FILM PARA TERMOFORMADORA) - MULTIPACK DIAMALER | BB16: =insumos!$I$265*9 -> 0.1936914 | BC16: 9 unid. X caja | BE16: 6229 | BF16: TAPA BARRERA NEGRA 250 C (FILM PARA TERMOFORMADORA) - MULTIPACK DIAMALER | BG16: =insumos!$I$265*12 -> 0.2582552 | BH16: 12 unid. X caja | BK16: Total | BL16: =SUM(BL7:BL15) -> 1.4003298 | BO16: 5403 | BP16: BOLSA VACIO 31X45 UMI - MERCOPACK | BQ16: =insumos!$H$80*4 -> 0.884 | BR16: 4 unid. X caja | BT16: 4972 | BU16: BOLSA VACIO 24x40 impr. TAURUS GOLD - MERCOPACK | BV16: =insumos!$H$71*12 -> 1.452 | BW16: 12 unid. X caja | BY16: 5202 | BZ16: Etiqueta Trasera | CA16: =insumos!$H$114*15 -> 0.39517143 | CB16: 15 unid. X caja | CD16: 5462 | CE16: BOLSA VACIO 30x65/ø45 UMi - BEMIS | CF16: =insumos!$H$76*16 -> 3.3024111 | CG16: 16 unid. X caja | CI16: 6216 | CJ16: ETIQUETAS BOPP MET.DOBLE CAPA 084X081 - ASADO 1 COSTILLA CONGELADO | CK16: =insumos!$H$181*8 -> 0.784 | CN16: 5202 | CO16: Etiqueta Trasera | CP16: =insumos!$H$114*16 -> 0.42151619 | CQ16: 16 unid. X caja | CS16: 5138 | CT16: ET. BOPP TERM. 102X78 - RR | CU16: =insumos!$H$113*16 -> 0.43215126 | CV16: 16 unid. X caja | CY16: Total | CZ16: =SUM(CZ7:CZ15) -> 5.2379763 | DC16: 5202 | DD16: Etiqueta Trasera | DE16: =insumos!$H$114*12 -> 0.31613714 | DF16: 12 unid. X caja | DH16: 6297 | DI16: BOLSA PARA VACIO 18X45 | DJ16: =insumos!$H$53*12 -> 1.872 | DK16: 12 unid. X caja | DM16: 6229 | DN16: TAPA BARRERA NEGRA 250 C (FILM PARA TERMOFORMADORA) - MULTIPACK DIAMALER | DO16: =insumos!$I$265*12 -> 0.2582552 | DP16: 12 unid. X caja | DS16: Total | DT16: =SUM(DT7:DT15) -> 2.7193883 | DX16: Total | DY16: =SUM(DY7:DY15) -> 6.1875025 | EF16: 45 moldes x 12,2 kls | EG16: =45*12.2 -> 549 | EJ16: Costo x kls | EL16: =EL15/EL17 -> 0.074824373
B17: 6229 | C17: TAPA BARRERA NEGRA 250 C (FILM PARA TERMOFORMADORA) - MULTIPACK DIAMALER | D17: =insumos!$I$265*12 -> 0.2582552 | E17: 12 unid. X caja | H17: peso prom. Caja | I17: 19.5 | M17: peso prom. Caja | N17: =29253.79/2456 -> 11.911152 | R17: Costo x kls | S17: =+S15/S16 -> 0.073075286 | W17: Costo x kls | X17: =+X15/X16 -> 0.11203478 | AB17: peso prom. Caja | AC17: 12.38 | AL17: Costo x kls | AM17: =+AM15/AM16 -> 0.28863741 | AP17: 6254 | AQ17: FONDO BARRERA TERMOFORMADORA TR NI 180 - MULTIPACK DIAMALER | AR17: =+insumos!$I$208*28 -> 1.2448086 | AS17: 28 unid. X caja | AU17: 6229 | AV17: TAPA BARRERA NEGRA 250 C (FILM PARA TERMOFORMADORA) - MULTIPACK DIAMALER | AW17: =insumos!$I$265*35 -> 0.75324433 | AZ17: 6254 | BA17: FONDO BARRERA TERMOFORMADORA TR NI 180 - MULTIPACK DIAMALER | BB17: =+insumos!$I$208*9 -> 0.40011705 | BC17: 9 unid. X caja | BE17: 6254 | BF17: FONDO BARRERA TERMOFORMADORA TR NI 180 - MULTIPACK DIAMALER | BG17: =+insumos!$I$208*12 -> 0.5334894 | BH17: 12 unid. X caja | BK17: peso prom. Caja | BL17: =146362.59/5379 -> 27.21 | BY17: 4741 | BZ17: BOLSA VACIO IMP. 20X50 - MERCOPACK | CA17: =insumos!$H$90*15 -> 4.62 | CB17: 15 unid. X caja | CN17: 5214 | CO17: BOLSA VACIO 18X67 SOLDA V SB15- MERCOPACK | CP17: =insumos!$H$65*16 -> 2.2079968 | CQ17: 16 unid. X caja | CS17: 5214 | CT17: BOLSA VACIO 18X67 SOLDA V SB15- MERCOPACK | CU17: =insumos!$H$65*16 -> 2.2079968 | CV17: 16 unid. X caja | CY17: peso prom. Caja | CZ17: 12.64 | DC17: 6229 | DD17: TAPA BARRERA NEGRA 250 C (FILM PARA TERMOFORMADORA) - MULTIPACK DIAMALER | DE17: =insumos!$I$265*12 -> 0.2582552 | DF17: 12 unid. X caja | DI17: Total | DJ17: =SUM(DJ7:DJ16) -> 5.6540897 | DM17: 6254 | DN17: FONDO BARRERA TERMOFORMADORA TR NI 180 - MULTIPACK DIAMALER | DO17: =+insumos!$I$208*12 -> 0.5334894 | DP17: 12 unid. X caja | DS17: peso prom. Caja | DT17: 18.09 | DX17: peso prom. Caja | DY17: =125974.25/7458 -> 16.891157 | EF17: Costo por tons. | EG17: =(+EG15/EG16)*1000 -> 58.440989 | EJ17: Peso Prom. Caja | EK17: ASADO 5 C | EL17: 19.9
B18: 6254 | C18: FONDO BARRERA TERMOFORMADORA TR NI 180 - MULTIPACK DIAMALER | D18: =+insumos!$I$208*12 -> 0.5334894 | E18: 12 unid. X caja | H18: Costo x kls | I18: =+I16/I17 -> 0.17745577 | M18: Costo x kls | N18: =+N16/N17 -> 0.22273278 | R18: porcentaje cobertura ( fallas, roturas) + 3 % | S18: =S17*1.03 -> 0.075267545 | W18: porcentaje cobertura ( fallas, roturas) + 3 % | X18: =X17*1.03 -> 0.11539582 | AB18: Costo x kls | AC18: =+AC16/AC17 -> 0.43917417 | AL18: porcentaje cobertura ( fallas, roturas) + 3 % | AM18: =AM17*1.03 -> 0.29729653 | AP18: 5868 | AQ18: PADS BLANCOS 4.5" x 7" - TITE DRI | AR18: =insumos!$I$243*28 -> 0.53088 | AS18: 28 unid. X caja | AU18: 6254 | AV18: FONDO BARRERA TERMOFORMADORA TR NI 180 - MULTIPACK DIAMALER | AW18: =+insumos!$I$208*35 -> 1.5560107 | AZ18: 6138 | BA18: FAJAS UMI - 8x19.5cm - IMPRIMEX | BB18: =insumos!$H$197*9 -> 1.3087059 | BC18: 9 unid. X caja | BE18: 6288 | BF18: ETIQUETAS BOPP MET. ADC 6000 60X110 LAMINADO MATE - EL RANCHO PASSION - RR | BG18: =insumos!$H$176*12 -> 0.648 | BH18: 12 unid. X caja | BK18: Costo x kls | BL18: =+BL16/BL17 -> 0.051463793 | CE18: Total | CF18: =SUM(CF7:CF17) -> 5.9848858 | CO18: Total | CP18: =SUM(CP7:CP17) -> 6.4771368 | CT18: Total | CU18: =SUM(CU7:CU17) -> 6.4877719 | CY18: Costo x kls | CZ18: =+CZ16/CZ17 -> 0.41439686 | DC18: 6254 | DD18: FONDO BARRERA TERMOFORMADORA TR NI 180 - MULTIPACK DIAMALER | DE18: =+insumos!$I$208*12 -> 0.5334894 | DF18: 12 unid. X caja | DI18: peso prom. Caja | DJ18: 12.14 | DM18: 5868 | DN18: PADS BLANCOS 4.5" x 7" - TITE DRI | DO18: =insumos!$I$243*12 -> 0.22752 | DP18: 12 unid. X caja | DS18: Costo x kls | DT18: =+DT16/DT17 -> 0.1503255 | DX18: Costo x kls | DY18: =+DY16/DY17 -> 0.36631608 | EF18: 3 % cobertura | EG18: =+EG17*1.03 -> 60.194218 | EK18: ASADO 8 C | EL18: 20.24
C19: Total | D19: =SUM(D7:D18) -> 4.9975966 | H19: porcentaje cobertura ( fallas, roturas) + 3 % | I19: =I18*1.03 -> 0.18277944 | M19: porcentaje cobertura ( fallas, roturas) + 3 % | N19: =N18*1.03 -> 0.22941476 | AB19: porcentaje cobertura ( fallas, roturas) + 3 % | AC19: =AC18*1.03 -> 0.4523494 | AQ19: Total | AR19: =SUM(AR7:AR18) -> 6.0726339 | BA19: Total | BB19: =SUM(BB7:BB18) -> 4.6362437 | BF19: Total | BG19: =SUM(BG7:BG18) -> 4.7005286 | BK19: porcentaje cobertura ( fallas, roturas) + 3 % | BL19: =BL18*1.03 -> 0.053007707 | BP19: Total | BQ19: =SUM(BQ7:BQ18) -> 3.2663234 | BU19: Total | BV19: =SUM(BV7:BV18) -> 3.9900309 | BZ19: Total | CA19: =SUM(CA7:CA18) -> 7.6805212 | CE19: peso prom. Caja | CF19: =1900.61/143 -> 13.290979 | CJ19: Total | CK19: =SUM(CK7:CK18) -> 5.0051925 | CO19: peso prom. Caja | CP19: =1992.58/164 -> 12.149878 | CT19: peso prom. Caja | CU19: =309.64/26 -> 11.909231 | CY19: porcentaje cobertura ( fallas, roturas) + 3 % | CZ19: =CZ18*1.03 -> 0.42682876 | DC19: 5868 | DD19: PADS BLANCOS 4.5" x 7" - TITE DRI | DE19: =+insumos!$I$243*12 -> 0.22752 | DF19: 12 unid. X caja | DI19: Costo x kls | DJ19: =+DJ17/DJ18 -> 0.4657405 | DN19: Total | DO19: =SUM(DO7:DO18) -> 3.7923999 | DS19: porcentaje cobertura ( fallas, roturas) + 3 % | DT19: =DT18*1.03 -> 0.15483526 | DX19: porcentaje cobertura ( fallas, roturas) + 3 % | DY19: =DY18*1.03 -> 0.37730557 | EF19: Cantidad Cajas x pallets | EG19: 30
C20: peso prom. Caja | D20: 12.89 | Q20: 998006 | R20: Envase Aguja | V20: 993032 | W20: Envase Vacio grueso (3x paquete) | AG20: Total | AH20: =SUM(AH7:AH15) -> 2.7314269 | AK20: 1987039 | AL20: Envase Falda c/h Vila | AQ20: peso prom. Caja | AR20: 10.5 | AV20: Total | AW20: =SUM(AW7:AW19) -> 6.7616437 | BA20: peso prom. Caja | BB20: =3178.57/286 -> 11.113881 | BF20: peso prom. Caja | BG20: =1659.9/151 -> 10.992715 | BP20: peso prom. Caja | BQ20: =1766.6/164 -> 10.771951 | BU20: peso prom. Caja | BV20: =16204.12/1282 -> 12.639719 | BZ20: peso prom. Caja | CA20: 13.25 | CE20: Costo x kls | CF20: =+CF18/CF19 -> 0.45029684 | CJ20: peso prom. Caja | CK20: =1042.85/124 -> 8.4100806 | CO20: Costo x kls | CP20: =+CP18/CP19 -> 0.53310303 | CT20: Costo x kls | CU20: =+CU18/CU19 -> 0.54476834 | DD20: Total | DE20: =SUM(DE7:DE19) -> 5.0885692 | DI20: porcentaje cobertura ( fallas, roturas) + 3 % | DJ20: =DJ19*1.03 -> 0.47971272 | DN20: peso prom. Caja | DO20: 5.1 | EF20: Costo $ por kls
C21: Costo x kls | D21: =+D19/D20 -> 0.38771114 | G21: 437024 | H21: Envase Colita de Cuadril | I21: 538 | J21: =I21/E2 -> 13.36314 | L21: 436035 | M21: Envase Matambre | N21: 240 | O21: =N21/E2 -> 5.9612519 | Q21: Código | R21: Insumos | S21: Precio U$S | V21: Código | W21: Insumos | X21: Precio U$S | AA21: 991420 | AB21: Envase Brazuelo s/h c/conical | AG21: peso prom. Caja | AH21: 12.62 | AK21: Código | AL21: Insumos | AM21: Precio U$S | AQ21: Costo x kls | AR21: =+AR19/AR20 -> 0.57834609 | AV21: peso prom. Caja | AW21: 11.3 | BA21: Costo x kls | BB21: =+BB19/BB20 -> 0.41715794 | BF21: Costo x kls | BG21: =+BG19/BG20 -> 0.42760396 | BP21: Costo x kls | BQ21: =+BQ19/BQ20 -> 0.30322486 | BU21: Costo x kls | BV21: =+BV19/BV20 -> 0.31567401 | BZ21: Costo x kls | CA21: =+CA19/CA20 -> 0.57966197 | CE21: porcentaje cobertura ( fallas, roturas) + 3 % | CF21: =CF20*1.03 -> 0.46380574 | CJ21: Costo x kls | CK21: =+CK19/CK20 -> 0.59514204 | CO21: porcentaje cobertura ( fallas, roturas) + 3 % | CP21: =CP20*1.03 -> 0.54909612 | CT21: porcentaje cobertura ( fallas, roturas) + 3 % | CU21: =CU20*1.03 -> 0.56111139 | CX21: 3193572 | CY21: Envase Entraña gruesa (GF) | DD21: peso prom. Caja | DE21: =4724.26/388 -> 12.175928 | DN21: Costo x kls | DO21: =+DO19/DO20 -> 0.74360783 | DR21: 6112731 | DS21: Envase Bife Angosto | DW21: 2366136 | DX21: Envase Picada | EF21: Unidades x caja. | EG21: 5 c = 5 o 6u
C22: porcentaje cobertura ( fallas, roturas) + 3 % | D22: =D21*1.03 -> 0.39934248 | G22: Código | H22: Insumos | I22: Precio U$S | L22: Código | M22: Insumos | N22: Precio U$S | R22: Envasado | W22: Envasado | AA22: Código | AB22: Insumos | AC22: Precio U$S | AG22: Costo x kls | AH22: =+AH20/AH21 -> 0.21643636 | AL22: Envasado | AQ22: porcentaje cobertura ( fallas, roturas) + 3 % | AR22: =AR21*1.03 -> 0.59569647 | AV22: Costo x kls | AW22: =+AW20/AW21 -> 0.59837555 | BA22: porcentaje cobertura ( fallas, roturas) + 3 % | BB22: =BB21*1.03 -> 0.42967267 | BF22: porcentaje cobertura ( fallas, roturas) + 3 % | BG22: =BG21*1.03 -> 0.44043208 | BP22: porcentaje cobertura ( fallas, roturas) + 3 % | BQ22: =BQ21*1.03 -> 0.31232161 | BU22: porcentaje cobertura ( fallas, roturas) + 3 % | BV22: =BV21*1.03 -> 0.32514424 | BZ22: porcentaje cobertura ( fallas, roturas) + 3 % | CA22: =CA21*1.03 -> 0.59705183 | CJ22: porcentaje cobertura ( fallas, roturas) + 3 % | CK22: =CK21*1.03 -> 0.6129963 | CX22: Código | CY22: Insumos | CZ22: Precio U$S | DD22: Costo x kls | DE22: =+DE20/DE21 -> 0.41792045 | DH22: 5516072 | DI22: Envase Entraña gruesa INK | DN22: porcentaje cobertura ( fallas, roturas) + 3 % | DO22: =DO21*1.03 -> 0.76591607 | DR22: Código | DS22: Insumos | DT22: Precio U$S | DW22: Código | DX22: Insumos | DY22: Precio U$S | EG22: 8c = 2 u
H23: Envasado | M23: Envasado | Q23: 6184 | R23: Fondo Congelado | S23: =insumos!$H$215 -> 0.6 | V23: 6184 | W23: Fondo Congelado | X23: =insumos!$H$215 -> 0.6 | AB23: Envasado | AG23: porcentaje cobertura ( fallas, roturas) + 3 % | AH23: =AH22*1.03 -> 0.22292945 | AK23: 6184 | AL23: Fondo Congelado | AM23: =insumos!$H$215 -> 0.6 | AV23: porcentaje cobertura ( fallas, roturas) + 3 % | AW23: =AW22*1.03 -> 0.61632681 | CD23: 4545460 | CE23: Envasado Asado c/h 4c UMI | CN23: 4858460 | CO23: Envase Asado 4/C en Tira Brasil | CS23: 6173460 | CT23: Envase Asado c/h 4c UMI | CY23: Envasado | DD23: porcentaje cobertura ( fallas, roturas) + 3 % | DE23: =DE22*1.03 -> 0.43045806 | DH23: Código | DI23: Insumos | DJ23: Precio U$S | DS23: Envasado | DX23: Envasado | EF23: porcentaje cobertura ( fallas, roturas) + 3 % | EH23: =EL16*1.03 -> 0.077069105
B24: 439011 | C24: Envase Tapa de Aguja | D24: =595 -> 595 | E24: =D24/E2 -> 14.778937 | G24: 5524 | H24: FONDO ENFRIADO (nueva medida) 505x380x155 cm - MERCOPACK | I24: =insumos!$H$217 -> 0.895 | L24: 5524 | M24: FONDO ENFRIADO (nueva medida) 505x380x155 cm - MERCOPACK | N24: =insumos!$H$217 -> 0.895 | Q24: 2037 | R24: Tapa blanca congelado | S24: =+insumos!$H$268 -> 0.65 | V24: 2037 | W24: Tapa blanca congelado | X24: =+insumos!H268 -> 0.65 | AA24: 6184 | AB24: Fondo Congelado | AC24: =insumos!$H$215 -> 0.6 | AK24: 5523 | AL24: TAPA VILA gris - 50x38x15.5 cm (nueva medida) - Mercopack | AM24: =+insumos!$H$285 -> 1.1829611 | AP24: 3673931 | AQ24: Envase Bife Angosto Porcionado | AZ24: 441033 | BA24: Envasado Bife de Vacio | BE24: 442070 | BF24: Envasado Entraña Fina EL RANCHO | BO24: 3516460 | BP24: Envasado Asado s/h 4c UMI | BT24: 4516160 | BU24: Envasado Asado c/h 3c Taurus | BY24: 4543860 | BZ24: Envasado Asado 4c tiras Vila | CD24: Código | CE24: Insumos | CF24: Precio U$S | CI24: 4546931 | CJ24: Envasado B.Angosto INK 300g | CN24: Código | CO24: Insumos | CP24: Precio U$S | CS24: Código | CT24: Insumos | CU24: Precio U$S | CX24: 3741 | CY24: Fondo cofre | CZ24: =insumos!$G$213 -> 0.83558719 | DI24: Envasado | DM24: 1993929 | DN24: Envasado Cuadril TG Porcionado | DR24: 5524 | DS24: FONDO ENFRIADO (nueva medida) 505x380x155 cm - MERCOPACK | DT24: =insumos!$H$217 -> 0.895 | DW24: 5524 | DX24: FONDO ENFRIADO (nueva medida) 505x380x155 cm - MERCOPACK | DY24: =insumos!$H$217 -> 0.895
B25: Código | C25: Insumos | D25: Precio U$S | G25: 5523 | H25: TAPA VILA gris - 50x38x15.5 cm (nueva medida) - Mercopack | I25: =+insumos!$H$285 -> 1.1829611 | L25: 2055 | M25: TAPA BLANCA 136 (cartulina)- Mpack | N25: =+insumos!$H$266 -> 1.15 | Q25: 4542 | R25: Bolsa 95X60 | S25: =insumos!$I$35 -> 0.022058824 | V25: 4542 | W25: Bolsa 95X60 | X25: =insumos!I35 -> 0.022058824 | AA25: 2037 | AB25: Tapa blanca congelado | AC25: =+insumos!$H$268 -> 0.65 | AF25: 885407 | AG25: Quijada Angus | AK25: 4542 | AL25: Bolsa 95X60 | AM25: =insumos!$I$35 -> 0.022058824 | AP25: Código | AQ25: Insumos | AR25: Precio U$S | AZ25: Código | BA25: Insumos | BB25: Precio U$S | BE25: Código | BF25: Insumos | BG25: Precio U$S | BO25: Código | BP25: Insumos | BQ25: Precio U$S | BT25: Código | BU25: Insumos | BV25: Precio U$S | BY25: Código | BZ25: Insumos | CA25: Precio U$S | CE25: Envasado | CI25: Código | CJ25: Insumos | CK25: Precio U$S | CO25: Envasado | CT25: Envasado | CX25: 3759 | CY25: TAPA VILA COFRE 156 (135)(gris) - Mpack | CZ25: =+insumos!$G$284 -> 1.1352417 | DC25: 4861032 | DD25: Envase Vacio Grueso (rojo) - Fralda | DH25: 3741 | DI25: Fondo Cofre | DJ25: =insumos!$G$213 -> 0.83558719 | DM25: Código | DN25: Insumos | DO25: Precio U$S | DR25: 2055 | DS25: TAPA BLANCA 136 (cartulina)- Mpack | DT25: =+insumos!$H$266 -> 1.15 | DW25: 2055 | DX25: TAPA BLANCA 136 (cartulina)- Mpack | DY25: =+insumos!$H$266 -> 1.15
